2020-07-22 21:34:33,977 ERROR: Exception on /reset_password_request [POST] [in /home/test/microblog/venv/lib/python3.7/site-packages/flask/app.py:1892]
Traceback (most recent call last):
  File "/home/test/microblog/venv/lib/python3.7/site-packages/flask/app.py", line 2447, in wsgi_app
    response = self.full_dispatch_request()
  File "/home/test/microblog/venv/lib/python3.7/site-packages/flask/app.py", line 1952, in full_dispatch_request
    rv = self.handle_user_exception(e)
  File "/home/test/microblog/venv/lib/python3.7/site-packages/flask/app.py", line 1821, in handle_user_exception
    reraise(exc_type, exc_value, tb)
  File "/home/test/microblog/venv/lib/python3.7/site-packages/flask/_compat.py", line 39, in reraise
    raise value
  File "/home/test/microblog/venv/lib/python3.7/site-packages/flask/app.py", line 1950, in full_dispatch_request
    rv = self.dispatch_request()
  File "/home/test/microblog/venv/lib/python3.7/site-packages/flask/app.py", line 1936, in dispatch_request
    return self.view_functions[rule.endpoint](**req.view_args)
  File "/home/test/microblog/app/routes.py", line 208, in reset_password_request
    send_password_reset_email(user)
  File "/home/test/microblog/app/email.py", line 20, in send_password_reset_email
    send_email('[Microblog] Reset Your Password',
NameError: name 'send_email' is not defined
2020-07-22 21:35:53,641 ERROR: Exception on /reset_password_request [POST] [in /home/test/microblog/venv/lib/python3.7/site-packages/flask/app.py:1892]
Traceback (most recent call last):
  File "/home/test/microblog/venv/lib/python3.7/site-packages/flask/app.py", line 2447, in wsgi_app
    response = self.full_dispatch_request()
  File "/home/test/microblog/venv/lib/python3.7/site-packages/flask/app.py", line 1952, in full_dispatch_request
    rv = self.handle_user_exception(e)
  File "/home/test/microblog/venv/lib/python3.7/site-packages/flask/app.py", line 1821, in handle_user_exception
    reraise(exc_type, exc_value, tb)
  File "/home/test/microblog/venv/lib/python3.7/site-packages/flask/_compat.py", line 39, in reraise
    raise value
  File "/home/test/microblog/venv/lib/python3.7/site-packages/flask/app.py", line 1950, in full_dispatch_request
    rv = self.dispatch_request()
  File "/home/test/microblog/venv/lib/python3.7/site-packages/flask/app.py", line 1936, in dispatch_request
    return self.view_functions[rule.endpoint](**req.view_args)
  File "/home/test/microblog/app/routes.py", line 208, in reset_password_request
    send_password_reset_email(user)
  File "/home/test/microblog/app/email.py", line 20, in send_password_reset_email
    send_email('[Microblog] Reset Your Password',
NameError: name 'send_email' is not defined
2020-07-22 22:06:42,181 INFO: Microblog Startup [in /home/test/microblog/app/__init__.py:58]
2020-07-22 22:44:14,251 INFO: Microblog Startup [in /home/test/microblog/app/__init__.py:58]
2020-07-22 22:52:41,392 INFO: Microblog Startup [in /home/test/microblog/app/__init__.py:58]
2020-07-22 23:09:12,784 INFO: Microblog Startup [in /home/test/microblog/app/__init__.py:60]
2020-07-22 23:39:29,940 INFO: Microblog Startup [in /home/test/microblog/app/__init__.py:60]
2020-07-23 00:00:22,352 INFO: Microblog Startup [in /home/test/microblog/app/__init__.py:60]
2020-07-23 00:10:22,868 INFO: Microblog Startup [in /home/test/microblog/app/__init__.py:60]
2020-07-23 00:10:40,249 ERROR: Exception on /reset_password/eyJ0eXAiOiJKV1QiLCJhbGciOiJIUzI1NiJ9.eyJyZXNldF9wYXNzd29yZCI6MywiZXhwIjoxNTk1NDM0ODI5Ljk1OTY5MTV9.TWjZqAxB61ULxPSyKeShE-tqWkbi_7_234L1oZ9ie-4 [GET] [in /home/test/microblog/venv/lib/python3.7/site-packages/flask/app.py:1892]
Traceback (most recent call last):
  File "/home/test/microblog/venv/lib/python3.7/site-packages/flask/app.py", line 2447, in wsgi_app
    response = self.full_dispatch_request()
  File "/home/test/microblog/venv/lib/python3.7/site-packages/flask/app.py", line 1952, in full_dispatch_request
    rv = self.handle_user_exception(e)
  File "/home/test/microblog/venv/lib/python3.7/site-packages/flask/app.py", line 1821, in handle_user_exception
    reraise(exc_type, exc_value, tb)
  File "/home/test/microblog/venv/lib/python3.7/site-packages/flask/_compat.py", line 39, in reraise
    raise value
  File "/home/test/microblog/venv/lib/python3.7/site-packages/flask/app.py", line 1950, in full_dispatch_request
    rv = self.dispatch_request()
  File "/home/test/microblog/venv/lib/python3.7/site-packages/flask/app.py", line 1936, in dispatch_request
    return self.view_functions[rule.endpoint](**req.view_args)
  File "/home/test/microblog/app/routes.py", line 222, in reset_password
    form = ResetPasswordForm()
  File "/home/test/microblog/venv/lib/python3.7/site-packages/wtforms/form.py", line 208, in __call__
    return type.__call__(cls, *args, **kwargs)
  File "/home/test/microblog/venv/lib/python3.7/site-packages/flask_wtf/form.py", line 87, in __init__
    super(FlaskForm, self).__init__(formdata=formdata, **kwargs)
  File "/home/test/microblog/venv/lib/python3.7/site-packages/wtforms/form.py", line 268, in __init__
    super(Form, self).__init__(self._unbound_fields, meta=meta_obj, prefix=prefix)
  File "/home/test/microblog/venv/lib/python3.7/site-packages/wtforms/form.py", line 51, in __init__
    field = meta.bind_field(self, unbound_field, options)
  File "/home/test/microblog/venv/lib/python3.7/site-packages/wtforms/meta.py", line 27, in bind_field
    return unbound_field.bind(form=form, **options)
  File "/home/test/microblog/venv/lib/python3.7/site-packages/wtforms/fields/core.py", line 376, in bind
    return self.field_class(*self.args, **kw)
TypeError: __init__() got an unexpected keyword argument 'validator'
2020-07-23 00:13:04,181 ERROR: Exception on /reset_password/eyJ0eXAiOiJKV1QiLCJhbGciOiJIUzI1NiJ9.eyJyZXNldF9wYXNzd29yZCI6MywiZXhwIjoxNTk1NDM0ODI5Ljk1OTY5MTV9.TWjZqAxB61ULxPSyKeShE-tqWkbi_7_234L1oZ9ie-4 [GET] [in /home/test/microblog/venv/lib/python3.7/site-packages/flask/app.py:1892]
Traceback (most recent call last):
  File "/home/test/microblog/venv/lib/python3.7/site-packages/flask/app.py", line 2447, in wsgi_app
    response = self.full_dispatch_request()
  File "/home/test/microblog/venv/lib/python3.7/site-packages/flask/app.py", line 1952, in full_dispatch_request
    rv = self.handle_user_exception(e)
  File "/home/test/microblog/venv/lib/python3.7/site-packages/flask/app.py", line 1821, in handle_user_exception
    reraise(exc_type, exc_value, tb)
  File "/home/test/microblog/venv/lib/python3.7/site-packages/flask/_compat.py", line 39, in reraise
    raise value
  File "/home/test/microblog/venv/lib/python3.7/site-packages/flask/app.py", line 1950, in full_dispatch_request
    rv = self.dispatch_request()
  File "/home/test/microblog/venv/lib/python3.7/site-packages/flask/app.py", line 1936, in dispatch_request
    return self.view_functions[rule.endpoint](**req.view_args)
  File "/home/test/microblog/app/routes.py", line 222, in reset_password
    form = ResetPasswordForm()
  File "/home/test/microblog/venv/lib/python3.7/site-packages/wtforms/form.py", line 208, in __call__
    return type.__call__(cls, *args, **kwargs)
  File "/home/test/microblog/venv/lib/python3.7/site-packages/flask_wtf/form.py", line 87, in __init__
    super(FlaskForm, self).__init__(formdata=formdata, **kwargs)
  File "/home/test/microblog/venv/lib/python3.7/site-packages/wtforms/form.py", line 268, in __init__
    super(Form, self).__init__(self._unbound_fields, meta=meta_obj, prefix=prefix)
  File "/home/test/microblog/venv/lib/python3.7/site-packages/wtforms/form.py", line 51, in __init__
    field = meta.bind_field(self, unbound_field, options)
  File "/home/test/microblog/venv/lib/python3.7/site-packages/wtforms/meta.py", line 27, in bind_field
    return unbound_field.bind(form=form, **options)
  File "/home/test/microblog/venv/lib/python3.7/site-packages/wtforms/fields/core.py", line 376, in bind
    return self.field_class(*self.args, **kw)
TypeError: __init__() got an unexpected keyword argument 'validator'
2020-07-23 00:22:08,400 INFO: Microblog Startup [in /home/test/microblog/app/__init__.py:60]
