2020-07-12 18:15:11,631 INFO: Microblog Startup [in /home/test/microblog/app/__init__.py:50]
2020-07-14 23:35:31,000 INFO: Microblog Startup [in /home/test/microblog/app/__init__.py:50]
2020-07-20 00:08:08,939 INFO: Microblog Startup [in /home/test/microblog/app/__init__.py:50]
2020-07-20 00:15:55,321 INFO: Microblog Startup [in /home/test/microblog/app/__init__.py:50]
2020-07-20 00:17:09,345 INFO: Microblog Startup [in /home/test/microblog/app/__init__.py:50]
2020-07-20 00:17:36,993 INFO: Microblog Startup [in /home/test/microblog/app/__init__.py:50]
2020-07-20 00:19:14,829 INFO: Microblog Startup [in /home/test/microblog/app/__init__.py:50]
2020-07-20 23:30:54,106 INFO: Microblog Startup [in /home/test/microblog/app/__init__.py:50]
2020-07-20 23:49:24,799 INFO: Microblog Startup [in /home/test/microblog/app/__init__.py:50]
2020-07-21 00:11:27,578 INFO: Microblog Startup [in /home/test/microblog/app/__init__.py:50]
2020-07-21 00:15:39,817 INFO: Microblog Startup [in /home/test/microblog/app/__init__.py:50]
2020-07-21 00:37:31,883 INFO: Microblog Startup [in /home/test/microblog/app/__init__.py:50]
2020-07-21 01:14:13,100 INFO: Microblog Startup [in /home/test/microblog/app/__init__.py:50]
2020-07-21 22:48:31,833 INFO: Microblog Startup [in /home/test/microblog/app/__init__.py:50]
2020-07-21 22:48:39,359 ERROR: Exception on / [GET] [in /home/test/microblog/venv/lib/python3.7/site-packages/flask/app.py:1892]
Traceback (most recent call last):
  File "/home/test/microblog/venv/lib/python3.7/site-packages/flask/app.py", line 2447, in wsgi_app
    response = self.full_dispatch_request()
  File "/home/test/microblog/venv/lib/python3.7/site-packages/flask/app.py", line 1952, in full_dispatch_request
    rv = self.handle_user_exception(e)
  File "/home/test/microblog/venv/lib/python3.7/site-packages/flask/app.py", line 1821, in handle_user_exception
    reraise(exc_type, exc_value, tb)
  File "/home/test/microblog/venv/lib/python3.7/site-packages/flask/_compat.py", line 39, in reraise
    raise value
  File "/home/test/microblog/venv/lib/python3.7/site-packages/flask/app.py", line 1950, in full_dispatch_request
    rv = self.dispatch_request()
  File "/home/test/microblog/venv/lib/python3.7/site-packages/flask/app.py", line 1936, in dispatch_request
    return self.view_functions[rule.endpoint](**req.view_args)
  File "/home/test/microblog/venv/lib/python3.7/site-packages/flask_login/utils.py", line 272, in decorated_view
    return func(*args, **kwargs)
  File "/home/test/microblog/app/routes.py", line 24, in index
    posts = current_user.followed_post().all()
  File "/home/test/microblog/venv/lib/python3.7/site-packages/werkzeug/local.py", line 347, in __getattr__
    return getattr(self._get_current_object(), name)
AttributeError: 'User' object has no attribute 'followed_post'
2020-07-21 23:06:09,297 INFO: Microblog Startup [in /home/test/microblog/app/__init__.py:50]
2020-07-21 23:06:22,008 ERROR: Exception on /user/godhan [GET] [in /home/test/microblog/venv/lib/python3.7/site-packages/flask/app.py:1892]
Traceback (most recent call last):
  File "/home/test/microblog/venv/lib/python3.7/site-packages/flask/app.py", line 2447, in wsgi_app
    response = self.full_dispatch_request()
  File "/home/test/microblog/venv/lib/python3.7/site-packages/flask/app.py", line 1952, in full_dispatch_request
    rv = self.handle_user_exception(e)
  File "/home/test/microblog/venv/lib/python3.7/site-packages/flask/app.py", line 1821, in handle_user_exception
    reraise(exc_type, exc_value, tb)
  File "/home/test/microblog/venv/lib/python3.7/site-packages/flask/_compat.py", line 39, in reraise
    raise value
  File "/home/test/microblog/venv/lib/python3.7/site-packages/flask/app.py", line 1950, in full_dispatch_request
    rv = self.dispatch_request()
  File "/home/test/microblog/venv/lib/python3.7/site-packages/flask/app.py", line 1936, in dispatch_request
    return self.view_functions[rule.endpoint](**req.view_args)
  File "/home/test/microblog/venv/lib/python3.7/site-packages/flask_login/utils.py", line 272, in decorated_view
    return func(*args, **kwargs)
  File "/home/test/microblog/app/routes.py", line 80, in user
    return render_template('user.html', user = user, posts = posts)
  File "/home/test/microblog/venv/lib/python3.7/site-packages/flask/templating.py", line 140, in render_template
    ctx.app,
  File "/home/test/microblog/venv/lib/python3.7/site-packages/flask/templating.py", line 120, in _render
    rv = template.render(context)
  File "/home/test/microblog/venv/lib/python3.7/site-packages/jinja2/environment.py", line 1090, in render
    self.environment.handle_exception()
  File "/home/test/microblog/venv/lib/python3.7/site-packages/jinja2/environment.py", line 832, in handle_exception
    reraise(*rewrite_traceback_stack(source=source))
  File "/home/test/microblog/venv/lib/python3.7/site-packages/jinja2/_compat.py", line 28, in reraise
    raise value.with_traceback(tb)
  File "/home/test/microblog/app/templates/user.html", line 1, in top-level template code
    {% extends "base.html" %}
  File "/home/test/microblog/app/templates/base.html", line 37, in top-level template code
    {% block content %}{% endblock %}
  File "/home/test/microblog/app/templates/user.html", line 24, in block "content"
    {% include '_post.html' %}
  File "/home/test/microblog/venv/lib/python3.7/site-packages/jinja2/environment.py", line 832, in handle_exception
    reraise(*rewrite_traceback_stack(source=source))
  File "/home/test/microblog/venv/lib/python3.7/site-packages/jinja2/_compat.py", line 28, in reraise
    raise value.with_traceback(tb)
  File "/home/test/microblog/app/templates/_post.html", line 4, in template
    <td><a href = "{{url_for('user', username = {{ post.author.username }})}}">
jinja2.exceptions.TemplateSyntaxError: expected token ':', got '}'
2020-07-21 23:06:25,637 ERROR: Exception on /user/godhan [GET] [in /home/test/microblog/venv/lib/python3.7/site-packages/flask/app.py:1892]
Traceback (most recent call last):
  File "/home/test/microblog/venv/lib/python3.7/site-packages/flask/app.py", line 2447, in wsgi_app
    response = self.full_dispatch_request()
  File "/home/test/microblog/venv/lib/python3.7/site-packages/flask/app.py", line 1952, in full_dispatch_request
    rv = self.handle_user_exception(e)
  File "/home/test/microblog/venv/lib/python3.7/site-packages/flask/app.py", line 1821, in handle_user_exception
    reraise(exc_type, exc_value, tb)
  File "/home/test/microblog/venv/lib/python3.7/site-packages/flask/_compat.py", line 39, in reraise
    raise value
  File "/home/test/microblog/venv/lib/python3.7/site-packages/flask/app.py", line 1950, in full_dispatch_request
    rv = self.dispatch_request()
  File "/home/test/microblog/venv/lib/python3.7/site-packages/flask/app.py", line 1936, in dispatch_request
    return self.view_functions[rule.endpoint](**req.view_args)
  File "/home/test/microblog/venv/lib/python3.7/site-packages/flask_login/utils.py", line 272, in decorated_view
    return func(*args, **kwargs)
  File "/home/test/microblog/app/routes.py", line 80, in user
    return render_template('user.html', user = user, posts = posts)
  File "/home/test/microblog/venv/lib/python3.7/site-packages/flask/templating.py", line 140, in render_template
    ctx.app,
  File "/home/test/microblog/venv/lib/python3.7/site-packages/flask/templating.py", line 120, in _render
    rv = template.render(context)
  File "/home/test/microblog/venv/lib/python3.7/site-packages/jinja2/environment.py", line 1090, in render
    self.environment.handle_exception()
  File "/home/test/microblog/venv/lib/python3.7/site-packages/jinja2/environment.py", line 832, in handle_exception
    reraise(*rewrite_traceback_stack(source=source))
  File "/home/test/microblog/venv/lib/python3.7/site-packages/jinja2/_compat.py", line 28, in reraise
    raise value.with_traceback(tb)
  File "/home/test/microblog/app/templates/user.html", line 1, in top-level template code
    {% extends "base.html" %}
  File "/home/test/microblog/app/templates/base.html", line 37, in top-level template code
    {% block content %}{% endblock %}
  File "/home/test/microblog/app/templates/user.html", line 24, in block "content"
    {% include '_post.html' %}
  File "/home/test/microblog/venv/lib/python3.7/site-packages/jinja2/environment.py", line 832, in handle_exception
    reraise(*rewrite_traceback_stack(source=source))
  File "/home/test/microblog/venv/lib/python3.7/site-packages/jinja2/_compat.py", line 28, in reraise
    raise value.with_traceback(tb)
  File "/home/test/microblog/app/templates/_post.html", line 4, in template
    <td><a href = "{{url_for('user', username = {{ post.author.username }})}}">
jinja2.exceptions.TemplateSyntaxError: expected token ':', got '}'
2020-07-22 16:06:23,164 INFO: Microblog Startup [in /home/test/microblog/app/__init__.py:51]
2020-07-22 16:14:59,394 INFO: Microblog Startup [in /home/test/microblog/app/__init__.py:51]
2020-07-22 16:31:41,887 INFO: Microblog Startup [in /home/test/microblog/app/__init__.py:58]
2020-07-22 21:33:46,269 INFO: Microblog Startup [in /home/test/microblog/app/__init__.py:58]
